<?xml version="1.0" ?>
<robot xmlns:xacro="http://ros.org/wiki/xacro">
<xacro:macro name="motoman_sg650" params="prefix">
  <xacro:include filename="$(find motoman_resources)/urdf/common_materials.xacro"/>

  <!-- link list -->
  <link name="${prefix}base_link">
    <visual>
      <geometry>
        <mesh filename="package://motoman_sg650_support/meshes/sg650/visual/base_link.stl"/>
      </geometry>
      <xacro:material_yaskawa_blue/>
    </visual>
    <collision>
      <geometry>
        <mesh filename="package://motoman_sg650_support/meshes/sg650/collision/base_link.stl"/>
      </geometry>
    </collision>
  </link>
  <link name="${prefix}link_1_s">
    <visual>
      <geometry>
        <mesh filename="package://motoman_sg650_support/meshes/sg650/visual/link_1_s.stl"/>
        <mesh filename="package://motoman_sg650_support/meshes/sg650/visual/link_1_s-cable.stl"/>
      </geometry>
      <xacro:material_yaskawa_blue/>
    </visual>
    <collision>
      <geometry>
        <mesh filename="package://motoman_sg650_support/meshes/sg650/collision/link_1_s.stl"/>
      </geometry>
    </collision>
  </link>
  <link name="${prefix}link_2_l">
    <visual>
      <geometry>
        <mesh filename="package://motoman_sg650_support/meshes/sg650/visual/link_2_l.stl"/>
      </geometry>
      <xacro:material_yaskawa_blue/>
    </visual>
    <collision>
      <geometry>
        <mesh filename="package://motoman_sg650_support/meshes/sg650/collision/link_2_l.stl"/>
      </geometry>
    </collision>
  </link>
  <link name="${prefix}link_3_u">
    <visual>
      <geometry>
        <mesh filename="package://motoman_sg650_support/meshes/sg650/visual/link_3_u.stl"/>
      </geometry>
      <xacro:material_yaskawa_blue/>
    </visual>
    <collision>
      <geometry>
        <mesh filename="package://motoman_sg650_support/meshes/sg650/collision/link_3_u.stl"/>
      </geometry>
    </collision>
  </link>
  <link name="${prefix}link_4_r">
    <visual>
      <geometry>
        <mesh filename="package://motoman_sg650_support/meshes/sg650/visual/link_4_r.stl"/>
      </geometry>
      <xacro:material_yaskawa_blue/>
    </visual>
    <collision>
      <geometry>
        <mesh filename="package://motoman_sg650_support/meshes/sg650/collision/link_4_r.stl"/>
      </geometry>
    </collision>
  </link>
  <link name="${prefix}tool0"/>
  <!-- end of link list -->

  <!-- joint list -->
  <joint name="${prefix}joint_1_s" type="revolute">
    <parent link="${prefix}base_link"/>
    <child link="${prefix}link_1_s"/>
    <origin xyz="0 0 0.225" rpy="0 0 0" />
    <axis xyz="0 0 1" />
    <limit lower="-2.3911" upper="2.3911" effort="100" velocity="7.85"/>
  </joint>
  <joint name="${prefix}joint_2_l" type="revolute">
    <parent link="${prefix}link_1_s"/>
    <child link="${prefix}link_2_l"/>
    <origin xyz="0.350 0 0" rpy="0 0 0" />
    <axis xyz="0 0 1" />
    <limit lower="-2.61799" upper="2.61799" effort="100" velocity="12.7"/>
  </joint>
  <joint name="${prefix}joint_3_u" type="prismatic">
    <parent link="${prefix}link_2_l"/>
    <child link="${prefix}link_3_u"/>
    <origin xyz="0.300 0 0" rpy="0 0 0" />
    <axis xyz="0 0 1" />
    <limit lower="-0.210" upper="0.0" effort="150" velocity="1.300"/>
  </joint>
  <joint name="${prefix}joint_4_r" type="revolute">
    <parent link="${prefix}link_3_u"/>
    <child link="${prefix}link_4_r"/>
    <origin xyz="0 0 0" rpy="0 0 0" />
    <axis xyz="0 0 1" />
    <limit lower="-6.28319" upper="6.28319" effort="100" velocity="43.6"/>
  </joint>
  <joint name="${prefix}joint_4_r-tool0" type="fixed">
    <origin xyz="0 0 -0.085 " rpy="${pi} 0 0"/>
    <parent link="${prefix}link_4_r"/>
    <child link="${prefix}tool0"/>
  </joint>
  <!-- end of joint list -->

  <!-- ROS base_link to Robot Manufacturer World Coordinates transform -->
  <link name="${prefix}base" />
  <joint name="${prefix}base_link-base" type="fixed">
    <origin xyz="0 0 0" rpy="0 0 0"/>
    <parent link="${prefix}base_link"/>
    <child link="${prefix}base"/>
  </joint>

  </xacro:macro>
</robot>

